Workbook

Sheet UPAg_crops
A1: State | B1: Crop | C1: Season | D1: Year | E1: Area (lakh ha) | F1: Production (lakh t)
A2: Bihar | B2: Maize | C2: Kharif | D2: 2016-17 | E2: 2.41 | F2: 6.24
A3: Bihar | B3: Maize | C3: Kharif | D3: 2017-18 | E3: 2.23 | F3: 5.36
A4: Bihar | B4: Maize | C4: Kharif | D4: 2018-19 | E4: 2.23 | F4: 4.64
A5: Bihar | B5: Maize | C5: Kharif | D5: 2019-20 | E5: 2.09 | F5: 4.35
A6: Bihar | B6: Maize | C6: Kharif | D6: 2020-21 | E6: 1.94 | F6: 2.25
A7: Bihar | B7: Maize | C7: Kharif | D7: 2021-22 | E7: 1.74 | F7: 2.35
A8: Bihar | B8: Maize | C8: Kharif | D8: 2022-23 | E8: 1.81 | F8: 4.45
A9: Bihar | B9: Maize | C9: Kharif | D9: 2023-24 | E9: 2.16 | F9: 5.86
A10: Bihar | B10: Maize | C10: Kharif | D10: 2024-25 | E10: 1.93 | F10: 5.71
A11: Bihar | B11: Maize | C11: Kharif | D11: 2025-26 | E11: 2 | F11: 6.78
A12: Bihar | B12: Maize | C12: Rabi | D12: 2016-17 | E12: 4.79 | F12: 20.66
A13: Bihar | B13: Maize | C13: Rabi | D13: 2017-18 | E13: 4.54 | F13: 18.19
... A21: Bihar | B21: Maize | C21: Rabi | D21: 2025-26 | E21: 5.25 | F21: 39.28
A22: Bihar | B22: Maize | C22: Summer | D22: 2016-17
A23: Bihar | B23: Maize | C23: Summer | D23: 2017-18
A24: Bihar | B24: Maize | C24: Summer | D24: 2018-19
A25: Bihar | B25: Maize | C25: Summer | D25: 2019-20
A26: Bihar | B26: Maize | C26: Summer | D26: 2020-21
A27: Bihar | B27: Maize | C27: Summer | D27: 2021-22
A28: Bihar | B28: Maize | C28: Summer | D28: 2022-23 | E28: 1.58 | F28: 10.19
A29: Bihar | B29: Maize | C29: Summer | D29: 2023-24 | E29: 1.82 | F29: 10.72
A30: Bihar | B30: Maize | C30: Summer | D30: 2024-25 | E30: 1.54 | F30: 8.27
A31: Bihar | B31: Maize | C31: Summer | D31: 2025-26 | E31: 1.64 | F31: 9.72
A32: Bihar | B32: Maize | C32: Total | D32: 2016-17 | E32: 7.21 | F32: 26.9
A33: Bihar | B33: Maize | C33: Total | D33: 2017-18 | E33: 6.77 | F33: 23.55
A34: Bihar | B34: Maize | C34: Total | D34: 2018-19 | E34: 6.69 | F34: 24.83
A35: Bihar | B35: Maize | C35: Total | D35: 2019-20 | E35: 6.73 | F35: 20.03
A36: Bihar | B36: Maize | C36: Total | D36: 2020-21 | E36: 6.49 | F36: 20.84
A37: Bihar | B37: Maize | C37: Total | D37: 2021-22 | E37: 6.63 | F37: 26.69
A38: Bihar | B38: Maize | C38: Total | D38: 2022-23 | E38: 7.48 | F38: 43.8
A39: Bihar | B39: Maize | C39: Total | D39: 2023-24 | E39: 9.55 | F39: 57.09
... A191: Karnataka | B191: Maize | C191: Rabi | D191: 2025-26 | E191: 1.59 | F191: 5.81
A192: Karnataka | B192: Maize | C192: Summer | D192: 2016-17
A193: Karnataka | B193: Maize | C193: Summer | D193: 2017-18
A194: Karnataka | B194: Maize | C194: Summer | D194: 2018-19
A195: Karnataka | B195: Maize | C195: Summer | D195: 2019-20
A196: Karnataka | B196: Maize | C196: Summer | D196: 2020-21
A197: Karnataka | B197: Maize | C197: Summer | D197: 2021-22
A198: Karnataka | B198: Maize | C198: Summer | D198: 2022-23 | E198: 0.71 | F198: 2.67
...

Sheet Groundwater
A1: Stage of groundwater extraction by state
A2: Stage (%) = annual extraction / annual extractable resource. Safe <=70, semi-critical 70-90, critical 90-100, over-exploited >100.
A4: Stage of extraction (%), as printed | B4: 2017 | C4: 2020 | D4: 2022 | E4: 2023 | F4: 2024 | G4: Change 2017-2024 (pp)
A5: Bihar | B5: 45.76 | C5: 51.14 | D5: 44.94 | E5: 44.76 | F5: 45.54 | G5: =F5-B5 -> -0.22
A6: Haryana | B6: 136.91 | C6: 134.56 | D6: 134.14 | E6: 135.74 | F6: 135.96 | G6: =F6-B6 -> -0.95
A7: Karnataka | B7: 69.87 | C7: 64.85 | D7: 69.93 | E7: 66.26 | F7: 68.44 | G7: =F7-B7 -> -1.43
A8: Madhya Pradesh | B8: 54.76 | C8: 56.82 | D8: 59.1 | E8: 58.75 | F8: 58.4 | G8: =F8-B8 -> 3.64
A9: Maharashtra | B9: 54.62 | C9: 54.99 | D9: 54.68 | E9: 53.83 | F9: 52.99 | G9: =F9-B9 -> -1.63
A10: Punjab | B10: 165.77 | C10: 164.42 | D10: 165.99 | E10: 163.76 | F10: 156.87 | G10: =F10-B10 -> -8.9
A11: Rajasthan | B11: 139.88 | C11: 150.22 | D11: 151.07 | E11: 148.77 | F11: 149.86 | G11: =F11-B11 -> 9.98
A12: Tamil Nadu | B12: 80.94 | C12: 82.93 | D12: 75.59 | E12: 73.91 | F12: 74.26 | G12: =F12-B12 -> -6.68
A13: Telangana | B13: 65.45 | C13: 53.32 | D13: 41.6 | E13: 38.65 | F13: 45.91 | G13: =F13-B13 -> -19.54
A14: Uttar Pradesh | B14: 70.18 | C14: 68.83 | D14: 70.66 | E14: 70.76 | F14: 70.45 | G14: =F14-B14 -> 0.27
A15: All India | B15: 63.33 | C15: 61.6 | D15: 60.08 | E15: 59.26 | F15: 60.475 | G15: =F15-B15 -> -2.855
A17: Annual extraction (bcm) | B17: 2017 | C17: 2020 | D17: 2022 | E17: 2023 | F17: 2024
A18: Bihar | B18: 13.26 | C18: 13.02 | D18: 13.5 | E18: 13.75 | F18: 14.1
A19: Haryana | B19: 12.5 | C19: 11.61 | D19: 11.54 | E19: 11.8 | F19: 12.72
A20: Karnataka | B20: 10.34 | C20: 10.63 | D20: 11.22 | E20: 11.32 | F20: 11.55
A21: Madhya Pradesh | B21: 18.88 | C21: 18.97 | D21: 19.25 | E21: 19.3 | F21: 19.85
A22: Maharashtra | B22: 16.33 | C22: 16.63 | D22: 16.65 | E22: 16.66 | F22: 16.5
A23: Punjab | B23: 35.78 | C23: 33.85 | D23: 28.02 | E23: 27.8 | F23: 27.66
A24: Rajasthan | B24: 16.77 | C24: 16.63 | D24: 16.56 | E24: 16.74 | F24: 17.05
A25: Tamil Nadu | B25: 14.73 | C25: 14.67 | D25: 14.43 | E25: 14.42 | F25: 14.45
A26: Telangana | B26: 8.09 | C26: 8.01 | D26: 8 | E26: 8.09 | F26: 8.47
A27: Uttar Pradesh | B27: 45.84 | C27: 46.03 | D27: 46.14 | E27: 46.4 | F27: 46.76
A28: All India | B28: 248.69 | C28: 244.92 | D28: 239.16 | E28: 241.34 | F28: 245.646
A30: Annual extractable resource (bcm) | B30: 2017 | C30: 2020 | D30: 2022 | E30: 2023 | F30: 2024
A31: Bihar | B31: 28.99 | C31: 25.46 | D31: 30.04 | E31: 30.72 | F31: 30.95
A32: Haryana | B32: 9.13 | C32: 8.63 | D32: 8.61 | E32: 8.69 | F32: 9.36
A33: Karnataka | B33: 14.79 | C33: 16.4 | D33: 16.04 | E33: 17.08 | F33: 16.88
A34: Madhya Pradesh | B34: 34.47 | C34: 33.38 | D34: 32.58 | E34: 32.85 | F34: 33.99
A35: Maharashtra | B35: 29.9 | C35: 30.25 | D35: 30.45 | E35: 30.95 | F35: 31.15
A36: Punjab | B36: 21.58 | C36: 20.59 | D36: 17.07 | E36: 16.98 | F36: 17.63
A37: Rajasthan | B37: 11.99 | C37: 11.07 | D37: 10.96 | E37: 11.25 | F37: 11.37
A38: Tamil Nadu | B38: 18.2 | C38: 17.69 | D38: 19.09 | E38: 19.51 | F38: 19.46
A39: Telangana | B39: 12.37 | C39: 15.03 | D39: 19.25 | E39: 20.92 | F39: 18.44
A40: Uttar Pradesh | B40: 65.32 | C40: 66.88 | D40: 65.3 | E40: 65.57 | F40: 66.38
A41: All India | B41: 392.7 | C41: 397.62 | D41: 398.08 | E41: 407.21 | F41: 406.194
A43: Cross-check: computed stage (%) | B43: 2017 | C43: 2020 | D43: 2022 | E43: 2023 | F43: 2024 | G43: Max gap vs printed (pp)
A44: Bihar | B44: =B18/B31*100 -> 45.73991 | C44: =C18/C31*100 -> 51.139042 | D44: =D18/D31*100 -> 44.94008 | E44: =E18/E31*100 -> 44.759115 | F44: =F18/F31*100 -> 45.557351 | G44: =MAX(ABS(B44-B5),ABS(C44-C5),ABS(D44-D5),ABS(E44-E5),ABS(F44-F5)) -> 0.020089686
...

Sheet Rainfall
A1: Southwest monsoon rainfall (June-September) by state
A2: Actual and normal in mm; departure (%) = actual/normal - 1. Normals change slightly between IMD reports.
A4: Departure from normal (%), as printed | B4: 2015 | C4: 2016 | D4: 2017 | E4: 2018 | F4: 2019 | G4: 2020 | H4: 2021 | I4: 2022 | J4: 2023 | K4: 2024
A5: Bihar | B5: -0.27 | C5: -0.03 | E5: -0.25 | F5: 0.03 | G5: 0.25 | H5: 0.03 | I5: -0.31
A6: Haryana | B6: -0.37 | C6: -0.28 | E6: -0.05 | F6: -0.42 | G6: -0.14 | H6: 0.3 | I6: 0.09
A7: Karnataka | B7: -0.2 | C7: -0.15 | E7: -0.06 | F7: 0.23 | G7: 0.27 | H7: 0.03 | I7: 0.29
A8: Madhya Pradesh | B8: -0.11 | C8: 0.19 | E8: -0.08 | F8: 0.44 | G8: 0.05 | H8: 0 | I8: 0.23
A9: Maharashtra | B9: -0.27 | C9: 0.16 | E9: -0.08 | F9: 0.32 | G9: 0.16 | H9: 0.19 | I9: 0.23
A10: Punjab | B10: -0.31 | C10: -0.28 | E10: 0.16 | F10: -0.07 | G10: -0.17 | H10: -0.07 | I10: -0.06
A11: Rajasthan | B11: 0.1 | C11: 0.28 | E11: -0.06 | F11: 0.41 | G11: 0.08 | H11: 0.17 | I11: 0.37
A12: Tamil Nadu | B12: -0.1 | C12: -0.19 | E12: -0.08 | F12: 0.17 | G12: 0.27 | H12: 0.17 | I12: 0.45
A13: Telangana | B13: -0.2 | C13: 0.19 | E13: -0.03 | F13: 0.06 | G13: 0.46 | H13: 0.39 | I13: 0.46
A14: Uttar Pradesh | B14: -0.46 | C14: -0.14 | E14: -0.1 | F14: -0.09 | G14: -0.18 | H14: -0.05 | I14: -0.29
A16: Actual rainfall (mm) | B16: 2015 | C16: 2016 | D16: 2017 | E16: 2018 | F16: 2019 | G16: 2020 | H16: 2021 | I16: 2022 | J16: 2023 | K16: 2024
A17: Bihar | B17: 745 | C17: 994.1 | E17: 770.8 | F17: 1049.4 | G17: 1272.4 | H17: 1044.3 | I17: 683.7
A18: Haryana | B18: 287.9 | C18: 332.1 | E18: 436.1 | F18: 255.2 | G18: 376.1 | H18: 571.3 | I18: 464.7
A19: Karnataka | B19: 664.7 | C19: 710.8 | E19: 780.3 | F19: 1032.1 | G19: 1063.9 | H19: 865.4 | I19: 1075.2
A20: Madhya Pradesh | B20: 843.8 | C20: 1131 | E20: 873.1 | F20: 1351.1 | G20: 991.7 | H20: 942.7 | I20: 1169.5
A21: Maharashtra | B21: 733 | C21: 1164.9 | E21: 923.9 | F21: 1329.8 | G21: 1166.1 | H21: 1194.3 | I21: 1219.8
A22: Punjab | B22: 338 | C22: 352 | E22: 569.1 | F22: 434.5 | G22: 387.5 | H22: 436.8 | I22: 414
A23: Rajasthan | B23: 460.3 | C23: 535.8 | E23: 393.7 | F23: 583.7 | G23: 450.2 | H23: 485.3 | I23: 596
A24: Tamil Nadu | B24: 286 | C24: 257.8 | E24: 290.7 | F24: 401.6 | G24: 425.8 | H24: 393.4 | I24: 476.8
A25: Telangana | B25: 600.8 | C25: 899.8 | E25: 732.9 | F25: 806.9 | G25: 1095.8 | H25: 1044.2 | I25: 1072.7
A26: Uttar Pradesh | B26: 459.3 | C26: 731.5 | E26: 765.4 | F26: 719.9 | G26: 649.7 | H26: 749.2 | I26: 533.4
A28: Normal rainfall (mm) | B28: 2015 | C28: 2016 | D28: 2017 | E28: 2018 | F28: 2019 | G28: 2020 | H28: 2021 | I28: 2022 | J28: 2023 | K28: 2024
A29: Bihar | B29: 1027.6 | C29: 1027.6 | E29: 1027.6 | F29: 1017.2 | G29: 1017.2 | H29: 1017.2 | I29: 992.2
A30: Haryana | B30: 459.8 | C30: 459.8 | E30: 459.8 | F30: 438.6 | G30: 438.6 | H30: 438.6 | I30: 426
A31: Karnataka | B31: 832.2 | C31: 832.2 | E31: 832.2 | F31: 840.7 | G31: 840.7 | H31: 840.7 | I31: 831.8
A32: Madhya Pradesh | B32: 952.3 | C32: 952.3 | E32: 952.3 | F32: 940.6 | G32: 940.6 | H32: 940.6 | I32: 949.5
A33: Maharashtra | B33: 1007.3 | C33: 1007.3 | E33: 1007.3 | F33: 1004.2 | G33: 1004.2 | H33: 1004.2 | I33: 994.5
A34: Punjab | B34: 491.9 | C34: 491.9 | E34: 491.9 | F34: 467.3 | G34: 467.3 | H34: 467.3 | I34: 439.8
A35: Rajasthan | B35: 419 | C35: 419 | E35: 419 | F35: 415 | G35: 415 | H35: 415 | I35: 435.6
A36: Tamil Nadu | B36: 317 | C36: 317 | E36: 317 | F36: 341.9 | G36: 336 | H36: 336 | I36: 328.4
A37: Telangana | B37: 755.2 | C37: 755.2 | E37: 759.2 | F37: 759.6 | G37: 751.9 | H37: 751.9 | I37: 734.8
A38: Uttar Pradesh | B38: 846.1 | C38: 846.1 | E38: 846.1 | F38: 790.2 | G38: 790.2 | H38: 790.2 | I38: 746.2
A40: Cross-check: computed departure | B40: 2015 | C40: 2016 | D40: 2017 | E40: 2018 | F40: 2019 | G40: 2020 | H40: 2021 | I40: 2022 | J40: 2023 | K40: 2024
A41: Bihar | B41: =IF(B29="","",B17/B29-1) -> -0.27500973 | C41: =IF(C29="","",C17/C29-1) -> -0.032600234 | D41: =IF(D29="","",D17/D29-1) | E41: =IF(E29="","",E17/E29-1) -> -0.24990269 | F41: =IF(F29="","",F17/F29-1) -> 0.031655525 | G41: =IF(G29="","",G17/G29-1) -> 0.25088478 | H41: =IF(H29="","",H17/H29-1) -> 0.026641762 | I41: =IF(I29="","",I17/I29-1) -> -0.31092522 | ... K41: =IF(K29="","",K17/K29-1)
A42: Haryana | B42: =IF(B30="","",B18/B30-1) -> -0.3738582 | C42: =IF(C30="","",C18/C30-1) -> -0.27772945 | D42: =IF(D30="","",D18/D30-1) | E42: =IF(E30="","",E18/E30-1) -> -0.05154415 | F42: =IF(F30="","",F18/F30-1) -> -0.41814865 | G42: =IF(G30="","",G18/G30-1) -> -0.14249886 | H42: =IF(H30="","",H18/H30-1) -> 0.30255358 | I42: =IF(I30="","",I18/I30-1) -> 0.09084507 | ... K42: =IF(K30="","",K18/K30-1)
A43: Karnataka | B43: =IF(B31="","",B19/B31-1) -> -0.20127373 | C43: =IF(C31="","",C19/C31-1) -> -0.14587839 | D43: =IF(D31="","",D19/D31-1) | E43: =IF(E31="","",E19/E31-1) -> -0.062364816 | F43: =IF(F31="","",F19/F31-1) -> 0.22766742 | G43: =IF(G31="","",G19/G31-1) -> 0.26549304 | H43: =IF(H31="","",H19/H31-1) -> 0.029380278 | I43: =IF(I31="","",I19/I31-1) -> 0.29261842 | ... K43: =IF(K31="","",K19/K31-1)
A44: Madhya Pradesh | B44: =IF(B32="","",B20/B32-1) -> -0.11393468 | C44: =IF(C32="","",C20/C32-1) -> 0.18765095 | D44: =IF(D32="","",D20/D32-1) | E44: =IF(E32="","",E20/E32-1) -> -0.083167069 | F44: =IF(F32="","",F20/F32-1) -> 0.43642356 | G44: =IF(G32="","",G20/G32-1) -> 0.054327025 | H44: =IF(H32="","",H20/H32-1) -> 0.0022326175 | I44: =IF(I32="","",I20/I32-1) -> 0.2317009 | ... K44: =IF(K32="","",K20/K32-1)
...

Sheet Sugarcane
A1: Sugarcane area and production by state
A4: Area ('000 ha), RBI T80 | B4: 2014-15 | C4: 2015-16 | D4: 2016-17 | E4: 2017-18 | F4: 2018-19 | G4: 2019-20 | H4: 2020-21 | I4: 2021-22 | J4: 2022-23 | K4: Change 2015-16 to 2022-23
A5: Bihar | B5: 254.3 | C5: 244 | D5: 239.6 | E5: 233.8 | F5: 225.6 | G5: 223.9 | H5: 221.1 | I5: 211.2 | J5: 209.9 | K5: =IFERROR(J5/C5-1,"") -> -0.1397541
A6: Haryana | B6: 97 | C6: 93 | D6: 102 | E6: 114 | F6: 108.7 | G6: 96.3 | H6: 99 | I6: 107.7 | J6: 107.8 | K6: =IFERROR(J6/C6-1,"") -> 0.15913978
A7: Karnataka | B7: 480 | C7: 450 | D7: 397 | E7: 370.3 | F7: 471.2 | G7: 429 | H7: 443 | I7: 637 | J7: 694 | K7: =IFERROR(J7/C7-1,"") -> 0.54222222
A8: Madhya Pradesh | B8: 111 | C8: 103 | D8: 92 | E8: 98 | F8: 108 | G8: 125 | H8: 95 | I8: 93 | J8: 92 | K8: =IFERROR(J8/C8-1,"") -> -0.10679612
A9: Maharashtra | B9: 1030 | C9: 987 | D9: 633.3 | E9: 902 | F9: 1162.8 | G9: 822.4 | H9: 1142.8 | I9: 1261.7 | J9: 1359.3 | K9: =IFERROR(J9/C9-1,"") -> 0.37720365
A10: Punjab | B10: 94 | C10: 90 | D10: 88 | E10: 96 | F10: 95 | G10: 91 | H10: 89.3 | I10: 86.8 | J10: 90.2 | K10: =IFERROR(J10/C10-1,"") -> 0.0022222222
A11: Rajasthan | B11: 5.6 | C11: 6.1 | D11: 6.9 | E11: 5.4 | F11: 5.4 | G11: 4.5 | H11: 5 | I11: 4.2 | J11: 3.5 | K11: =IFERROR(J11/C11-1,"") -> -0.42622951
A12: Tamil Nadu | B12: 263.1 | C12: 252.3 | D12: 218.3 | E12: 171.9 | F12: 166.4 | G12: 131.2 | H12: 127.7 | I12: 148 | J12: 161.4 | K12: =IFERROR(J12/C12-1,"") -> -0.36028537
A13: Telangana | B13: 38 | C13: 35 | D13: 29 | E13: 35 | F13: 40 | G13: 26 | H13: 22 | I13: 28 | J13: 33 | K13: =IFERROR(J13/C13-1,"") -> -0.057142857
A14: Uttar Pradesh | B14: 2140.8 | C14: 2169 | D14: 2160 | E14: 2234 | F14: 2224 | G14: 2208 | H14: 2180 | I14: 2177 | J14: 2736.1 | K14: =IFERROR(J14/C14-1,"") -> 0.26145689
A15: All India | B15: 5066.8 | C15: 4927.1 | D15: 4435.7 | E15: 4737.1 | F15: 5061.1 | G15: 4602.7 | H15: 4851.2 | I15: 5175.4 | J15: 5883.5 | K15: =IFERROR(J15/C15-1,"") -> 0.19411013
A16: Source: RBI Handbook 2023, Table 80 (Ministry of Agriculture). 2022-23 = 3rd advance estimate (later revised, e.g. UP 2,795 in ICAR table).
A18: Area (lakh ha), ICAR-SBI | B18: 2018-19 | C18: 2019-20 | D18: 2020-21 | E18: 2021-22 | F18: 2022-23 | G18: 2023-24
A19: Bihar | B19: 2.26 | C19: 2.24 | D19: 2.19 | E19: 2.11 | F19: 2.1 | G19: 2.02
A20: Haryana | B20: 1.09 | C20: 0.96 | D20: 0.99 | E20: 1.08 | F20: 1.08 | G20: 0.9
A21: Karnataka | B21: 4.71 | C21: 4.29 | D21: 4.43 | E21: 6.37 | F21: 6.59 | G21: 6.26
A22: Madhya Pradesh | B22: 1.08 | C22: 1.25 | D22: 1.1 | E22: 0.93 | F22: 0.92 | G22: 1.02
A23: Maharashtra | B23: 11.63 | C23: 8.22 | D23: 11.43 | E23: 12.62 | F23: 13.59 | G23: 14
A24: Punjab | B24: 0.95 | C24: 0.91 | D24: 0.89 | E24: 0.87 | F24: 0.9 | G24: 0.96
A25: Tamil Nadu | B25: 1.66 | C25: 1.31 | D25: 1.25 | E25: 1.48 | F25: 1.59 | G25: 1.35
A26: Telangana | B26: 0.4 | C26: 0.26 | D26: 0.2 | E26: 0.28 | F26: 0.28 | G26: 0.27
A27: Uttar Pradesh | B27: 22.24 | C27: 22.08 | D27: 21.8 | E27: 21.77 | F27: 27.95 | G27: 25.28
A28: All India | B28: 50.61 | C28: 46.03 | D28: 48.57 | E28: 51.75 | F28: 58.85 | G28: 56.48
A30: Production (million t), ICAR-SBI | B30: 2018-19 | C30: 2019-20 | D30: 2020-21 | E30: 2021-22 | F30: 2022-23 | G30: 2023-24 | H30: Change 2018-19 to 2023-24
A31: Bihar | B31: 20.12 | C31: 13.58 | D31: 10.71 | E31: 12.03 | F31: 12.74 | G31: 11.39 | H31: =G31/B31-1 -> -0.43389662
A32: Haryana | B32: 8.51 | C32: 7.73 | D32: 8.53 | E32: 8.82 | F32: 8.86 | G32: 7.46 | H32: =G32/B32-1 -> -0.12338425
A33: Karnataka | B33: 42.41 | C33: 38.18 | D33: 42.09 | E33: 61.15 | F33: 59.35 | G33: 53.2 | H33: =G33/B33-1 -> 0.25442113
A34: Madhya Pradesh | B34: 5.28 | C34: 7.43 | D34: 5.88 | E34: 5.38 | F34: 6.44 | G34: 7.14 | H34: =G34/B34-1 -> 0.35227273
A35: Maharashtra | B35: 89.77 | C35: 69.31 | D35: 101.6 | E35: 116.08 | F35: 123.97 | G35: 105.99 | H35: =G35/B35-1 -> 0.18068397
A36: Punjab | B36: 7.77 | C36: 7.3 | D36: 7.49 | E36: 7.13 | F36: 7.51 | G36: 7.99 | H36: =G36/B36-1 -> 0.028314028
A37: Tamil Nadu | B37: 17.14 | C37: 14.12 | D37: 12.8 | E37: 16.17 | F37: 17.66 | G37: 14.41 | H37: =G37/B37-1 -> -0.15927655
A38: Telangana | B38: 3.18 | C38: 2.01 | D38: 1.36 | E38: 2.87 | F38: 2.94 | G38: 2.32 | H38: =G38/B38-1 -> -0.27044025
A39: Uttar Pradesh | B39: 179.71 | C39: 179.54 | D39: 177.67 | E39: 179.17 | F39: 224.25 | G39: 205.63 | H39: =G39/B39-1 -> 0.14423237
A40: All India | B40: 405.42 | C40: 370.5 | D40: 399.26 | E40: 439.43 | F40: 490.53 | G40: 446.43 | H40: =G40/B40-1 -> 0.10115436
A41: Source: ICAR-Sugarcane Breeding Institute, StatisticsAPY-23-24 (citing DES / E&S DAC); 2023-24 = 2nd advance estimate. Rajasthan not listed.
A43: Yield (kg/ha), Lok Sabha AU1760 | B43: 2015-16 | C43: 2016-17 | D43: 2017-18
A44: Bihar | B44: 51837 | C44: 54415 | D44: 59138
A45: Haryana | B45: 71957 | C45: 80618 | D45: 84499
...

Sheet Rice
A1: Rice area and production by state
A4: Area ('000 ha), RBI T69 | B4: 2014-15 | C4: 2015-16 | D4: 2016-17 | E4: 2017-18 | F4: 2018-19 | G4: 2019-20 | H4: 2020-21 | I4: 2021-22 | J4: 2022-23 | K4: Change 2015-16 to 2022-23
A5: Bihar | B5: 3263.4 | C5: 3232.3 | D5: 3339.8 | E5: 3307 | F5: 3159.7 | G5: 2886.4 | H5: 3020.9 | I5: 3091.4 | J5: 2940.6 | K5: =J5/C5-1 -> -0.090245336
A6: Haryana | B6: 1287 | C6: 1354 | D6: 1386 | E6: 1422 | F6: 1447 | G6: 1447 | H6: 1327.2 | I6: 1281 | J6: 1519.7 | K6: =J6/C6-1 -> 0.12237814
A7: Karnataka | B7: 1326 | C7: 1110 | D7: 1034 | E7: 993 | F7: 1139.1 | G7: 1185 | H7: 1397.1 | I7: 1397.9 | J7: 1300 | K7: =J7/C7-1 -> 0.17117117
A8: Madhya Pradesh | B8: 2153 | C8: 2024 | D8: 2289 | E8: 2035 | F8: 2391 | G8: 2016 | H8: 2117 | I8: 2109 | J8: 3413.8 | K8: =J8/C8-1 -> 0.68666008
A9: Maharashtra | B9: 1551 | C9: 1503 | D9: 1535.3 | E9: 1451 | F9: 1464.9 | G9: 1553 | H9: 1560.6 | I9: 1651.8 | J9: 1718.1 | K9: =J9/C9-1 -> 0.14311377
A10: Punjab | B10: 2894 | C10: 2975 | D10: 2898 | E10: 3065 | F10: 3103 | G10: 2920 | H10: 2928 | I10: 2969 | J10: 3028.5 | K10: =J10/C10-1 -> 0.017983193
A11: Rajasthan | B11: 167.8 | C11: 182.9 | D11: 197.8 | E11: 190.6 | F11: 197.8 | G11: 219.5 | H11: 231.5 | I11: 196.5 | J11: 234.3 | K11: =J11/C11-1 -> 0.28102788
A12: Tamil Nadu | B12: 1795 | C12: 2000.2 | D12: 1442.8 | E12: 1828.9 | F12: 1721.3 | G12: 1907.4 | H12: 2036.2 | I12: 2217.3 | J12: 2150.7 | K12: =J12/C12-1 -> 0.075242476
A13: Telangana | B13: 1415 | C13: 1046 | D13: 1682.2 | E13: 1962 | F13: 1932 | G13: 2011 | H13: 3186.4 | I13: 3654.9 | J13: 4548.4 | K13: =J13/C13-1 -> 3.3483748
A14: Uttar Pradesh | B14: 5872 | C14: 5862 | D14: 5992 | E14: 5814 | F14: 5748 | G14: 5737 | H14: 5678 | I14: 5703 | J14: 5796 | K14: =J14/C14-1 -> -0.011258956
A15: All India | B15: 44110.6 | C15: 43499.2 | D15: 43993.4 | E15: 43774.1 | F15: 44156.5 | G15: 43662.3 | H15: 45768.7 | I15: 46278.7 | J15: 47666.4 | K15: =J15/C15-1 -> 0.095799463
A16: Source: RBI Handbook 2023, Table 69 (Ministry of Agriculture). 2022-23 = 3rd advance estimate.
A18: Production ('000 t), RBI T60 | B18: 2014-15 | C18: 2015-16 | D18: 2016-17 | E18: 2017-18 | F18: 2018-19 | G18: 2019-20 | H18: 2020-21 | I18: 2021-22 | J18: 2022-23 | K18: Change 2015-16 to 2022-23
A19: Bihar | B19: 6356.7 | C19: 6802.2 | D19: 8239.3 | E19: 8093.1 | F19: 6155.5 | G19: 6298 | H19: 6747 | I19: 7717 | J19: 6725.2 | K19: =J19/C19-1 -> -0.011319867
A20: Haryana | B20: 4006 | C20: 4145 | D20: 4453 | E20: 4523.38 | F20: 4516.1 | G20: 4824.3 | H20: 4424.9 | I20: 4618 | J20: 5406.9 | K20: =J20/C20-1 -> 0.30443908
A21: Karnataka | B21: 3541 | C21: 3021 | D21: 2604.8 | E21: 3017.1 | F21: 3431 | G21: 3634.5 | H21: 4291.8 | I21: 4318.4 | J21: 4001.3 | K21: =J21/C21-1 -> 0.3244952
A22: Madhya Pradesh | B22: 3625.3 | C22: 3546.7 | D22: 4226.8 | E22: 4123.9 | F22: 4494.7 | G22: 4778.2 | H22: 4413.8 | I22: 4814.9 | J22: 7657.2 | K22: =J22/C22-1 -> 1.1589647
A23: Maharashtra | B23: 2946 | C23: 2593 | D23: 3109.5 | E23: 2730.8 | F23: 3275.7 | G23: 2897.6 | H23: 3291.7 | I23: 3598.1 | J23: 3899.1 | K23: =J23/C23-1 -> 0.50370228
A24: Punjab | B24: 11107 | C24: 11823 | D24: 11586.2 | E24: 13381.79 | F24: 12821.6 | G24: 11779.3 | H24: 12783.7 | I24: 12885.5 | J24: 13146.7 | K24: =J24/C24-1 -> 0.11195974
A25: Rajasthan | B25: 366.7 | C25: 369.8 | D25: 452.7 | E25: 450.87 | F25: 453.2 | G25: 480.5 | H25: 634 | I25: 478.6 | J25: 577.4 | K25: =J25/C25-1 -> 0.56138453
A26: Tamil Nadu | B26: 5727.8 | C26: 7517.1 | D26: 2369.4 | E26: 6638.9 | F26: 6130.9 | G26: 7171.1 | H26: 6881.2 | I26: 7906.6 | J26: 7850.6 | K26: =J26/C26-1 -> 0.044365513
A27: Telangana | B27: 4440.8 | C27: 3047 | D27: 5173.4 | E27: 6262.2 | F27: 6670 | G27: 7427.8 | H27: 10217.1 | I27: 12409.6 | J27: 16013.9 | K27: =J27/C27-1 -> 4.2556285
A28: Uttar Pradesh | B28: 12167.9 | C28: 12501 | D28: 13754 | E28: 13274 | F28: 15545.3 | G28: 15517.8 | H28: 15520 | I28: 15271.5 | J28: 15171.3 | K28: =J28/C28-1 -> 0.21360691
A29: All India | B29: 104798.5 | C29: 104408.2 | D29: 109698.4 | E29: 112757.6 | F29: 116477.8 | G29: 118870.3 | H29: 124368.3 | I29: 129471.4 | J29: 135542 | K29: =J29/C29-1 -> 0.29819305
A30: Source: RBI Handbook 2023, Table 60 (Ministry of Agriculture). Gap: 2023-24 and 2024-25 state values.

Sheet Coarse_cereals
A1: Coarse cereals area by state (maize + jowar + bajra + ragi + small millets + barley)
A2: Maize cannot be separated from millets in this table; state maize data is in the Gaps tab.
A4: Area ('000 ha), RBI T71 | B4: 2014-15 | C4: 2015-16 | D4: 2016-17 | E4: 2017-18 | F4: 2018-19 | G4: 2019-20 | H4: 2020-21 | I4: 2021-22 | J4: 2022-23 | K4: Change 2015-16 to 2022-23
A5: Bihar | B5: 732.7 | C5: 730 | D5: 745.1 | E5: 702.2 | F5: 699.8 | G5: 689.2 | H5: 667.1 | I5: 678.28 | J5: 671.87 | K5: =J5/C5-1 -> -0.079630137
A6: Haryana | B6: 474 | C6: 458 | D6: 565 | E6: 524 | F6: 485.8 | G6: 540.8 | H6: 616.4 | I6: 514.75 | J6: 573.2 | K6: =J6/C6-1 -> 0.25152838
A7: Karnataka | B7: 3349 | C7: 3223 | D7: 3179 | E7: 3438 | F7: 3013.2 | G7: 3262.6 | H7: 3509 | I7: 3230.4 | J7: 3302 | K7: =J7/C7-1 -> 0.024511325
A8: Madhya Pradesh | B8: 1794 | C8: 1848 | D8: 2086.6 | E8: 2211 | F8: 1841 | G8: 1921.9 | H8: 1947 | I8: 1971 | J8: 2085 | K8: =J8/C8-1 -> 0.12824675
A9: Maharashtra | B9: 5423 | C9: 5254 | D9: 5211.7 | E9: 4242.3 | F9: 3320 | G9: 4223.9 | H9: 4130.2 | I9: 3707.93 | J9: 3379.6 | K9: =J9/C9-1 -> -0.35675676
A10: Punjab | B10: 137 | C10: 124 | D10: 125.5 | E10: 122.7 | F10: 116.9 | G10: 121.3 | H10: 114.1 | I10: 111.4 | J10: 101.3 | K10: =J10/C10-1 -> -0.18306452
A11: Rajasthan | B11: 5986.5 | C11: 5818.3 | D11: 5938.9 | E11: 5906.6 | F11: 5825.8 | G11: 6132.5 | H11: 6177.4 | I11: 5514.98 | J11: 6481.03 | K11: =J11/C11-1 -> 0.11390441
A12: Tamil Nadu | B12: 859.3 | C12: 867.2 | D12: 718 | E12: 885 | F12: 924.1 | G12: 961.4 | H12: 980.4 | I12: 954.69 | J12: 922.18 | K12: =J12/C12-1 -> 0.063399446
A13: Telangana | B13: 784 | C13: 657 | D13: 911 | E13: 707 | F13: 608 | G13: 661 | H13: 361 | I13: 486.1 | J13: 582.7 | K13: =J13/C13-1 -> -0.1130898
A14: Uttar Pradesh | B14: 2010 | C14: 1966 | D14: 2008 | E14: 1971 | F14: 1914 | G14: 1989 | H14: 2023 | I14: 1995 | J14: 2021 | K14: =J14/C14-1 -> 0.027975585
A15: All India | B15: 25169.8 | C15: 24389.3 | D15: 25007.6 | E15: 24286.5 | F15: 22145.7 | G15: 23987.9 | H15: 24117.8 | I15: 22700.23 | J15: 23588.67 | K15: =J15/C15-1 -> -0.0328271
A16: Source: RBI Handbook 2023, Table 71 (Ministry of Agriculture). 2022-23 = 3rd advance estimate.

Sheet National_production
A1: All-India production by crop (lakh tonnes)
A2: Ragi = kharif only. 2025-26 = 3rd advance estimate.
A4: Year | B4: Rice | C4: Wheat | D4: Maize | E4: Jowar | F4: Bajra | G4: Ragi | H4: Sugarcane | I4: Status
A5: 2015-16 | B5: 1044.08 | C5: 922.88 | D5: 225.67 | E5: 42.38 | F5: 80.67 | G5: 18.22 | H5: 3484.48 | I5: final
A6: 2016-17 | B6: 1096.98 | C6: 985.1 | D6: 259 | E6: 45.68 | F6: 97.3 | G6: 13.85 | H6: 3060.69 | I6: final
A7: 2017-18 | B7: 1127.58 | C7: 998.7 | D7: 287.53 | E7: 48.03 | F7: 92.09 | G7: 19.85 | H7: 3799.05 | I7: final
A8: 2018-19 | B8: 1164.78 | C8: 1035.96 | D8: 277.15 | E8: 34.75 | F8: 86.64 | G8: 12.39 | H8: 4054.16 | I8: final
A9: 2019-20 | B9: 1188.7 | C9: 1078.61 | D9: 287.66 | E9: 47.72 | F9: 103.63 | G9: 17.55 | H9: 3705 | I9: final
A10: 2020-21 | B10: 1243.68 | C10: 1095.86 | D10: 316.47 | E10: 48.12 | F10: 108.63 | G10: 19.98 | H10: 4053.99 | I10: final
A11: 2021-22 | B11: 1294.71 | C11: 1077.42 | D11: 337.3 | E11: 41.51 | F11: 97.81 | G11: 17.01 | H11: 4394.25 | I11: final
A12: 2022-23 | B12: 1357.55 | C12: 1105.54 | D12: 380.85 | E12: 38.14 | F12: 114.31 | G12: 16.91 | H12: 4905.33 | I12: final
A13: 2023-24 | B13: 1378.25 | C13: 1132.92 | D13: 376.65 | E13: 47.37 | F13: 107.16 | G13: 16.7 | H13: 4531.58 | I13: final
A14: 2024-25 | B14: 1501.84 | C14: 1179.45 | D14: 434.09 | E14: 49.55 | F14: 112.05 | G14: 19.77 | H14: 4546.11 | I14: final
A15: 2025-26 | B15: 1540.24 | C15: 1206.57 | D15: 550.93 | E15: 43.56 | F15: 108.48 | G15: 20 | H15: 5000.63 | I15: 3rd AE
A16: Change 2015-16 to 2024-25 | B16: =B14/B5-1 -> 0.43843384 | C16: =C14/C5-1 -> 0.27801014 | D16: =D14/D5-1 -> 0.92356095 | E16: =E14/E5-1 -> 0.16918358 | F16: =F14/F5-1 -> 0.38899219 | G16: =G14/G5-1 -> 0.08507135 | H16: =H14/H5-1 -> 0.30467387
A18: Source: DES, Ministry of Agriculture, Time Series of 3rd Advance Estimates 2025-26 (as on 27 May 2026).

Sheet MSP_FRP
A1: Minimum support prices and sugarcane FRP (Rs per quintal)
A2: Kharif crops by marketing season; wheat by crop year (marketed in the following rabi season); FRP by sugar season.
A4: Crop | B4: Basis | C4: 2015-16 | D4: 2016-17 | E4: 2017-18 | F4: 2018-19 | G4: 2019-20 | H4: 2020-21 | I4: 2021-22 | J4: 2022-23 | K4: 2023-24 | L4: 2024-25 | M4: 2025-26 | N4: Change 2015-16 to 2024-25 | O4: Step-up 2018-19 vs 2017-18
A5: Paddy (common) | B5: KMS | C5: 1410 | D5: 1470 | E5: 1550 | F5: 1750 | G5: 1815 | H5: 1868 | I5: 1940 | J5: 2040 | K5: 2183 | L5: 2300 | M5: 2369 | N5: =L5/C5-1 -> 0.63120567 | O5: =F5/E5-1 -> 0.12903226
A6: Maize | B6: KMS | C6: 1325 | D6: 1365 | E6: 1425 | F6: 1700 | G6: 1760 | H6: 1850 | I6: 1870 | J6: 1962 | K6: 2090 | L6: 2225 | M6: 2400 | N6: =L6/C6-1 -> 0.67924528 | O6: =F6/E6-1 -> 0.19298246
A7: Jowar (hybrid) | B7: KMS | C7: 1570 | D7: 1625 | E7: 1700 | F7: 2430 | G7: 2550 | H7: 2620 | I7: 2738 | J7: 2970 | K7: 3180 | L7: 3371 | M7: 3699 | N7: =L7/C7-1 -> 1.1471338 | O7: =F7/E7-1 -> 0.42941176
A8: Bajra | B8: KMS | C8: 1275 | D8: 1330 | E8: 1425 | F8: 1950 | G8: 2000 | H8: 2150 | I8: 2250 | J8: 2350 | K8: 2500 | L8: 2625 | M8: 2775 | N8: =L8/C8-1 -> 1.0588235 | O8: =F8/E8-1 -> 0.36842105
A9: Ragi | B9: KMS | C9: 1650 | D9: 1725 | E9: 1900 | F9: 2897 | G9: 3150 | H9: 3295 | I9: 3377 | J9: 3578 | K9: 3846 | L9: 4290 | M9: 4886 | N9: =L9/C9-1 -> 1.6 | O9: =F9/E9-1 -> 0.52473684
A10: Tur (arhar) | B10: KMS | C10: 4625 | D10: 5050 | E10: 5450 | F10: 5675 | G10: 5800 | H10: 6000 | I10: 6300 | J10: 6600 | K10: 7000 | L10: 7550 | M10: 8000 | N10: =L10/C10-1 -> 0.63243243 | O10: =F10/E10-1 -> 0.041284404
A11: Moong | B11: KMS | C11: 4850 | D11: 5225 | E11: 5575 | F11: 6975 | G11: 7050 | H11: 7196 | I11: 7275 | J11: 7755 | K11: 8558 | L11: 8682 | M11: 8768 | N11: =L11/C11-1 -> 0.79010309 | O11: =F11/E11-1 -> 0.25112108
A12: Urad | B12: KMS | C12: 4625 | D12: 5000 | E12: 5400 | F12: 5600 | G12: 5700 | H12: 6000 | I12: 6300 | J12: 6600 | K12: 6950 | L12: 7400 | M12: 7800 | N12: =L12/C12-1 -> 0.6 | O12: =F12/E12-1 -> 0.037037037
A13: Wheat | B13: crop year (RMS = next year) | C13: 1525 | D13: 1625 | E13: 1735 | F13: 1840 | G13: 1925 | H13: 1975 | I13: 2015 | J13: 2125 | K13: 2275 | L13: 2425 | M13: 2585 | N13: =L13/C13-1 -> 0.59016393 | O13: =F13/E13-1 -> 0.060518732
A14: Sugarcane FRP | B14: sugar season | C14: 230 | D14: 230 | E14: 255 | F14: 275 | G14: 275 | H14: 285 | I14: 290 | J14: 305 | K14: 315 | L14: 340 | M14: 355 | N14: =L14/C14-1 -> 0.47826087 | O14: =F14/E14-1 -> 0.078431373
A15: FRP base recovery % | B15: sugar season | C15: 9.5 | D15: 9.5 | E15: 9.5 | F15: 10 | G15: 10 | H15: 10 | I15: 10 | J15: 10.25 | K15: 10.25 | L15: 10.25 | M15: 10.25
A16: FRP is fixed for a base recovery rate that rose from 9.5% to 10% (2018-19) and 10.25% (2022-23). At 9.5% recovery the 2024-25 floor was Rs 315.10, a 37.0% rise on 2015-16, not 47.8%.
A17: Sources: DES MSP statement (12 Dec 2025) for 2021-22 onward; CACP/Government MSP compilation (S.P. University copy) for 2015-16 to 2020-21; FRP base rates from Cabinet decisions (see Source_Log).

Sheet Ethanol
A1: National ethanol series (ethanol supply years)
A2: ESY ran Dec-Nov until 2021-22, then Nov-Oct. Blended and supplied volumes are different measures.
A4: ESY | B4: Blended (crore L) | C4: Blending % | D4: Supplied (crore L) | E4: Source | F4: Note
A5: 2013-14 | B5: 38 | C5: 0.0153 | E5: Lok Sabha AU2832 (8 Aug 2024)
A6: 2018-19 | B6: 188.6 | C6: 0.05 | E6: MoPNG website (Ethanol Blended Petrol page)
A7: 2019-20 | F7: not found in an official source yet
A8: 2020-21 | B8: 302.3 | C8: 0.0817 | E8: Lok Sabha reply (via Indian Chemical News 9 Aug 2024) | F8: Dataful (MoPNG) shows 332 crore L / 8.5%
A9: 2021-22 | B9: 433.6 | C9: 0.1 | E9: Dataful dataset 21604 (MoPNG); 10% reached Jun 2022 per MoPNG
A10: 2022-23 | B10: 508.5 | C10: 0.1206 | E10: Lok Sabha AU2832 (12.06%); volume Dataful 21604 | F10: 11-month year (Dec-Oct)
A11: 2023-24 | B11: 707.4 | C11: 0.146 | D11: 672.49 | E11: Blending %: MoPNG (iamrenew 18 Apr 2025); blended volume: Dataful 21604; supplied: Indian Express Oct 2025 | F11: blended vs supplied differ
A12: 2024-25 | B12: 1022.4 | C12: 0.192 | D12: 1039 | E12: PPAC via BioEnergy Times 20 Nov 2025 (blended); AIDA via Outlook Business 20 Feb 2026 (supplied) | F12: 20% first reached Oct 2025
A14: ESY | B14: Feedstock | C14: Value | D14: Unit | E14: Source
A15: 2023-24 | B15: Total supplied | C15: 672.49 | D15: crore L | E15: Indian Express (Oct 2025) via Vision IAS
A16: 2023-24 | B16: Grain-based | C16: 402.22 | D16: crore L | E16: Indian Express (Oct 2025) via Vision IAS
A17: 2023-24 | B17: of which maize | C17: 286.47 | D17: crore L | E17: Indian Express (Oct 2025) via Vision IAS
A18: 2023-24 | B18: of which broken/damaged grain | C18: 115.62 | D18: crore L | E18: Indian Express (Oct 2025) via Vision IAS
A19: 2023-24 | B19: Sugarcane-based | C19: 270.27 | D19: crore L | E19: Indian Express (Oct 2025) via Vision IAS
A20: 2023-24 | B20: Maize share | C20: 42.74 | D20: % | E20: Down To Earth 14 Aug 2025
A21: 2024-25 | B21: Total supplied | C21: 1039 | D21: crore L | E21: AIDA via Outlook Business 20 Feb 2026
A22: 2024-25 | B22: Grain-based | C22: 718 | D22: crore L | E22: AIDA via Outlook Business 20 Feb 2026
A23: 2024-25 | B23: Sugarcane-based | C23: 321 | D23: crore L | E23: AIDA via Outlook Business 20 Feb 2026
A24: 2024-25 | B24: Maize share | C24: 48-51 | D24: % | E24: AIDA via Outlook Business 20 Feb 2026
A25: 2021-22 | B25: Maize share | C25: 0 | D25: % | E25: Rajya Sabha reply MoS Petroleum 20 Jul 2026 (ANI)
A26: 2025-26 | B26: Maize share | C26: ~37 | D26: % | E26: Rajya Sabha reply MoS Petroleum 20 Jul 2026 (ANI)
A27: 2023-24 | B27: Sugar diversion cap | C27: 1.7 | D27: million t | E27: DFPD directive 15 Dec 2023 via Argus Media
B28: Grain share 2023-24 (computed) | C28: =C16/C15 -> 0.59810555
B29: Grain share 2024-25 (computed) | C29: =C22/C21 -> 0.69104909
B30: Maize share 2023-24 (computed) | C30: =C17/C15 -> 0.42598403
A32: Period | B32: Feedstock | C32: Price | D32: Unit | E32: Source
A33: 2023-24 | B33: C-heavy molasses | C33: 56.58 | D33: Rs per L | E33: CCEA decision Jan 2025 (Khan Global summary)
A34: 2024-25 | B34: C-heavy molasses | C34: 57.97 | D34: Rs per L | E34: CCEA decision Jan 2025 (Khan Global summary)
A35: 2024-25 | B35: B-heavy molasses | C35: 60.73 | D35: Rs per L | E35: CCEA decision Jan 2025 (Khan Global summary)
A36: 2024-25 | B36: Cane juice / sugar / syrup | C36: 65.61 | D36: Rs per L | E36: CCEA decision Jan 2025 (Khan Global summary)
A37: 2022-23 | B37: Maize (from 22 Aug 2023) | C37: 66.07 | D37: Rs per L | E37: Lok Sabha AU755 (7 Feb 2024)
A38: 2023-24 | B38: Maize | C38: 71.86 | D38: Rs per L | E38: Lok Sabha AU755 (7 Feb 2024)
A39: 2020 | B39: FCI rice to distilleries | C39: 2250 | D39: Rs per quintal | E39: Policy Circle (28 Jul 2023)
A40: Dec 2020 | B40: FCI rice to distilleries | C40: 2000 | D40: Rs per quintal | E40: Policy Circle (28 Jul 2023)
A41: 2024-25 (before Jan 2025) | B41: FCI rice reserve price | C41: 2800 | D41: Rs per quintal | E41: iamrenew (21 Jan 2025)
A42: 2024-25 (from Jan 2025) | B42: FCI rice reserve price | C42: 2250 | D42: Rs per quintal | E42: iamrenew (21 Jan 2025)
A44: Item | B44: Period | C44: Value | D44: Unit | E44: Source
...

Sheet Source_Log
A1: Source log
A2: Every source was opened and checked on 25 Oct 2026. Type: Official / Official via media / Compiled official / Institutional / Media.
A4: Tab | B4: Data | C4: Document / table | D4: Original agency | E4: Type | F4: URL | G4: Note
A5: Groundwater | B5: Stage of extraction, extraction, resource 2017-2024 | C5: RBI Handbook 2024-25, Table 107 (11 Dec 2025) | D5: CGWB, Ministry of Jal Shakti | E5: Compiled official | F5: https://rbi.org.in/ScriptS/PublicationsView.aspx?id=23556 | G5: Punjab 2022 conflict noted
A6: Groundwater | B6: Punjab 2017-2024 stage of extraction | C6: Dynamic Ground Water Resources & Quality of Punjab, 2024 | D6: CGWB | E6: Official | F6: https://cgwb.gov.in/cgwbpnm/public/uploads/documents/1742295732461871757file.pdf | G6: Used for Punjab 2022 correction
A7: Groundwater | B7: 2017 and 2020 extraction totals (cross-check) | C7: Lok Sabha AU3018 | D7: Ministry of Jal Shakti | E7: Official | F7: https://eparlib.sansad.in/bitstream/123456789/1059876/1/AU3018.pdf | G7: Matches RBI exactly
A8: Groundwater | B8: Bihar 2024 extraction by use (10.21 irrigation of 14.09 bcm) | C8: Dynamic Ground Water Resources of Bihar, 2024 | D8: CGWB / Govt of Bihar | E8: Official | F8: https://www.cgwb.gov.in/cgwbpnm/public/uploads/documents/1743584819841710360file.pdf | G8: Example of state split; others pending
A9: Rainfall | B9: Monsoon rainfall 2013-2016 | C9: Lok Sabha US 4446 (14 Dec 2016) | D9: MoES / IMD | E9: Official | F9: https://moes.gov.in/sites/default/files/LS_US_4446_14122016.pdf | G9: 2015, 2016 used
A10: Rainfall | B10: Monsoon and annual rainfall 2018-2020 | C10: Rajya Sabha 165 (3 Aug 2021) | D10: MoES / IMD | E10: Official | F10: https://www.moes.gov.in/sites/default/files/RS-English-165-03082021.pdf | G10: 2020 rows misaligned; not used
A11: Rainfall | B11: Monsoon rainfall 2020-2022 | C11: Rajya Sabha 25 (27 Jul 2023) | D11: MoES / IMD | E11: Official | F11: https://www.moes.gov.in/sites/default/files/RS-in-25-27-07-2023.pdf
A12: Sugarcane | B12: Area 2014-15 to 2022-23 | C12: RBI Handbook 2023, Table 80 | D12: Ministry of Agriculture | E12: Compiled official | F12: https://rbi.org.in/Scripts/PublicationsView.aspx?id=22144
A13: Sugarcane | B13: Area, production, yield 2018-19 to 2023-24 | C13: State-wise APY of sugarcane (StatisticsAPY-23-24) | D13: ICAR-SBI citing DES | E13: Official | F13: https://sugarcane.icar.gov.in/wp-content/uploads/2024/08/StatisticsAPY-23-24.pdf | G13: 2023-24 = 2nd AE
A14: Sugarcane | B14: Yield 2015-16 to 2018-19 | C14: Lok Sabha AU1760 (2 Jul 2019) | D14: Ministry of Agriculture | E14: Official | F14: https://eparlib.nic.in/bitstream/123456789/951428/1/AU1760.pdf
A15: Sugarcane | B15: Area 2013-14 to 2017-18 (cross-check) | C15: Lok Sabha AU443 (5 Feb 2019) | D15: Ministry of Agriculture | E15: Official | F15: https://eparlib.nic.in/bitstream/123456789/806271/1/AU443.pdf | G15: Matches RBI T80
A16: UPAg_crops | B16: State area and production by crop and season, 2016-17 to 2025-26 | C16: UPAg State Profile: Crop-wise APY (dash.upag.gov.in/stateprofile) | D16: DA&FW / DES, Ministry of Agriculture | E16: Official | F16: https://upag.gov.in/dash-reports/stateprofile | G16: Read via browser; 2025-26 = 3rd advance estimate; All India matches DES time series
A17: Rice | B17: Area 2004-05 to 2022-23 | C17: RBI Handbook 2023, Table 69 | D17: Ministry of Agriculture | E17: Compiled official | F17: https://www.rbi.org.in/Scripts/PublicationsView.aspx?id=22133
A18: Rice | B18: Production 2014-15 to 2022-23 | C18: RBI Handbook 2023, Table 60 | D18: Ministry of Agriculture | E18: Compiled official | F18: https://www.rbi.org.in/Scripts/PublicationsView.aspx?id=22124
A19: Coarse_cereals | B19: Area 2014-15 to 2022-23 | C19: RBI Handbook 2023, Table 71 | D19: Ministry of Agriculture | E19: Compiled official | F19: https://rbi.org.in/scriptS/PublicationsView.aspx?id=22135
A20: National_production | B20: All-India production 2015-16 to 2025-26 | C20: Time Series, 3rd Advance Estimates 2025-26 | D20: DES, Ministry of Agriculture | E20: Official | F20: https://desagri.gov.in/wp-content/uploads/2026/06/Time-Series-3rd-AE-2025-26-English.pdf
A21: MSP_FRP | B21: MSP 2021-22 to 2025-26 | C21: MSP statement as on 12 Dec 2025 | D21: DES / CACP | E21: Official | F21: https://desagri.gov.in/wp-content/uploads/2025/12/MSP-Statement_English_As-on-12.12.2025.pdf
A22: MSP_FRP | B22: MSP and FRP 2012-13 to 2021-22 | C22: MSP recommended by CACP and fixed by Government | D22: CACP / Government of India | E22: Compiled official | F22: https://www.spuvvn.edu/academic_centres/c_c_s/MSP_SINCE_2012_13.pdf | G22: Matches DES for overlapping 2021-22
A23: MSP_FRP | B23: FRP 2015-16 at 9.5% recovery | C23: Cabinet decision, 16 Jan 2015 (report) | D23: CCEA | E23: Official via media | F23: https://www.ap7am.com/en/6592/centre-raises-sugarcane-price-to-rs230-per-quintal
A24: MSP_FRP | B24: FRP 2017-18 at 9.5% recovery | C24: Cabinet decision, 24 May 2017 (report) | D24: CCEA | E24: Official via media | F24: https://www.millenniumpost.in/nation/nation-243599
A25: MSP_FRP | B25: FRP 2018-19 to 2022-23 base rates (10%, then 10.25%) | C25: Business Standard topic page, Cabinet decisions | D25: CCEA | E25: Official via media | F25: https://www.business-standard.com/topic/sugarcane-frp
A26: MSP_FRP | B26: FRP 2024-25 Rs 340 at 10.25%; Rs 315.10 at 9.5% | C26: Cabinet decision Feb 2024 | D26: CCEA | E26: Official | F26: https://www.narendramodi.in/cabinet-approves-frp-of-sugarcane-payable-by-sugar-factories-for-sugar-season-2024-25
A27: MSP_FRP | B27: FRP 2025-26 Rs 355 at 10.25% | C27: Cabinet decision 30 Apr 2025 (PTI) | D27: CCEA | E27: Official via media | F27: https://www.theweek.in/wire-updates/business/2025/04/30/del51-cab-sugarcane.html
A28: Ethanol | B28: Blending 2013-14 and 2022-23; forex savings | C28: Lok Sabha AU2832 (8 Aug 2024) | D28: MoPNG | E28: Official | F28: https://eparlib.nic.in/bitstream/123456789/2980100/1/AU2832_aKas3t.pdf
A29: Ethanol | B29: ESY 2018-19 procurement and blending | C29: Ethanol Blended Petrol page | D29: MoPNG | E29: Official | F29: https://mopng.gov.in/en/refining/ethanol-blended-petrol
A30: Ethanol | B30: ESY 2020-21 302.3 crore L, 8.17% | C30: Lok Sabha reply reported 9 Aug 2024 | D30: MoPNG | E30: Official via media | F30: https://www.indianchemicalnews.com/general/lite/increase-in-blending-of-ethanol-22815
A31: Ethanol | B31: Blended volumes 2020-21 to 2024-25 | C31: Dataful dataset 21604 | D31: MoPNG (per Dataful) | E31: Compiled official | F31: https://dataful.in/datasets/21604/ | G31: Secondary; used where Parliament gives no volume
A32: Ethanol | B32: ESY 2023-24 % blending; 20% announcement | C32: iamrenew, 18 Apr 2025 | D32: MoPNG | E32: Official via media | F32: https://www.iamrenew.com/green-energy/india-achieves-20-ethanol-blending-sets-sight-on-30-by-2030/
A33: Ethanol | B33: ESY 2024-25 average 19.2%, 1,022.4 crore L | C33: BioEnergy Times, 20 Nov 2025 | D33: PPAC | E33: Official via media | F33: https://bioenergytimes.com/esy-2024-25-india-achieves-20-ethanol-blending-in-october/
A34: Ethanol | B34: ESY 2023-24 feedstock split | C34: Indian Express explainer via Vision IAS (13 Oct 2025) | D34: Not named | E34: Media | F34: https://visionias.in/current-affairs/upsc-daily-news-summary/article/2025-10-13/the-indian-express/economy/how-grain-not-sugar-is-fuelling-indias-ethanol-production | G34: Trace to MoPNG in Stage 3
A35: Ethanol | B35: ESY 2024-25 feedstock split | C35: Outlook Business, 20 Feb 2026 | D35: AIDA | E35: Media (industry data) | F35: https://www.outlookbusiness.com/industry/maize-leads-esy-2024-25-ethanol-feedstock-shift | G35: Industry body figures
A36: Ethanol | B36: Maize share 0% (2021-22) to ~37% (2025-26) | C36: Rajya Sabha reply 20 Jul 2026 (ANI) | D36: MoPNG | E36: Official via media | F36: https://thedailyguardian.com/business/centre-assures-20-ethanol-blending-target-has-no-impact-on-indias-food-security-or-water-stress20260720183632-739371/
A37: Ethanol | B37: Maize share 42.74% (2023-24) | C37: Down To Earth, 14 Aug 2025 | D37: Not named | E37: Media | F37: https://www.downtoearth.org.in/agriculture/biofuels-area-under-maize-cultivation-in-india-increases-sharply-driven-by-push-for-ethanol
A38: Ethanol | B38: Molasses and juice ethanol prices 2023-24, 2024-25 | C38: CCEA decision Jan 2025 (summary) | D38: CCEA | E38: Official via media | F38: https://currentaffairs.khanglobalstudies.com/cabinet-approves-revised-ethanol-procurement-price-for-ebp-programme-2024-25/ | G38: Replace with PIB original
A39: Ethanol | B39: Maize ethanol prices 2022-23, 2023-24 | C39: Lok Sabha AU755 (7 Feb 2024) | D39: DFPD | E39: Official | F39: https://eparlib.nic.in/bitstream/123456789/2974643/1/AU755.pdf
A40: Ethanol | B40: FCI rice prices and quantities 2020-2023 | C40: Policy Circle explainer, 28 Jul 2023 | D40: FCI / DFPD | E40: Media | F40: https://www.policycircle.org/economy/fci-rice-for-ethanol-explainer/
A41: Ethanol | B41: FCI rice resumed Aug 2024, 23 lakh t | C41: Deccan Herald (PTI), 29 Aug 2024 | D41: DFPD | E41: Official via media | F41: https://www.deccanherald.com/amp/story/business%2Fgovt-allows-sale-of-23-lakh-tonnes-of-rice-from-food-corporation-of-indias-stock-to-ethanol-makers-3169620
...

Sheet Gaps
A1: Data still missing, and where to get it
A2: Priority A blocks a hypothesis test; B weakens it; C is for Stage 4.
A4: Priority | B4: Missing data | C4: Needed for | D4: Best source | E4: Why not collected | F4: Link
A5: A | B5: State groundwater extraction split by irrigation / industry / domestic | C5: H4 (agriculture's share of depletion) | D5: CGWB National Compilation 2024, Annexure I | E5: Annexure beyond the reader's page limit | F5: https://cgwb.gov.in/cgwbpnm/publication-detail/1326
A6: B | B6: State stage of extraction for 2025 | C6: H4 (latest point) | D6: CGWB National Compilation 2025 | E6: Not yet opened | F6: https://data.opencity.in/dataset/national-compilation-of-dynamic-ground-water-resources-of-india-2025
A7: B | B7: Annual pre- and post-monsoon water levels by state | C7: H4 yearly series | D7: CGWB Ground Water Year Books / India-WRIS | E7: gwdata.cgwb.gov.in in maintenance | F7: https://ckandev.indiadataportal.com/dataset/groundwater
A8: B | B8: Monsoon rainfall 2017, 2023, 2024 by state | C8: H4 rainfall control | D8: IMD end-of-season reports / MoES Parliament answers | E8: Not found as state table yet | F8: https://mausam.imd.gov.in/
A9: B | B9: Ethanol 2019-20 volume; feedstock split 2018-19 to 2022-23; sugar diverted by year; FCI rice actually lifted | C9: H1 series | D9: MoPNG / DFPD Parliament answers; ISMA; FCI annual reports | E9: Scattered across answers | F9: https://sansad.in/
A10: B | B10: Irrigated area by source (tubewell vs canal) by state | C10: H4 groundwater share | D10: DES Land Use Statistics; RBI Handbook Tables 55-56 | E10: RBI new site redirects | F10: https://website.rbi.org.in/web/rbi/-/publications/table-56-state-wise-pattern-of-land-use-net-irrigated-area
A11: B | B11: Distillery capacity by state and feedstock | C11: H1 state allocation | D11: DFPD | E11: Not published as a table found so far | F11: https://dfpd.gov.in/
A12: C | B12: Cost of cultivation and returns per hectare by state | C12: H3 profitability | D12: CACP price policy reports | E12: Stage 3-4 | F12: https://cacp.da.gov.in/
A13: C | B13: Farm electricity subsidy by state; artificial recharge cost per m3 | C13: H5 cost translation | D13: PFC utility performance report; CGWB Master Plan 2020 | E13: Stage 4 | F13: https://cgwb.gov.in/cgwbpnm/public/uploads/documents/168613326251844776file.pdf

Sheet Analysis_H1
A1: H1: share of national output going to ethanol
A2: Feedstock (lakh t) = ethanol (crore L) x 1e7 / litres per tonne / 1e5. Blue cells are inputs; black cells are formulas.
A4: Feedstock | B4: Year | C4: Ethanol low (crore L) | D4: Ethanol high (crore L) | E4: Yield low (L/t) | F4: Yield high (L/t) | G4: Production (lakh t) | H4: Feedstock low (lakh t) | I4: Feedstock high (lakh t) | J4: Share low | K4: Share high
A5: Maize | B5: 2023-24 | C5: 286.47 | D5: 286.47 | E5: 380 | F5: 400 | G5: 376.65 | H5: =C5*10000000/F5/100000 -> 71.6175 | I5: =D5*10000000/E5/100000 -> 75.386842 | J5: =H5/G5 -> 0.19014337 | K5: =I5/G5 -> 0.20015091
A6: Maize | B6: 2024-25 | C6: =0.48*1039 -> 498.72 | D6: =0.51*1039 -> 529.89 | E6: 380 | F6: 400 | G6: 434.09 | H6: =C6*10000000/F6/100000 -> 124.68 | I6: =D6*10000000/E6/100000 -> 139.44474 | J6: =H6/G6 -> 0.28722154 | K6: =I6/G6 -> 0.32123462
A7: Rice and broken grain | B7: 2023-24 | C7: 115.62 | D7: 115.62 | E7: 370 | F7: 470 | G7: 1378.25 | H7: =C7*10000000/F7/100000 -> 24.6 | I7: =D7*10000000/E7/100000 -> 31.248649 | J7: =H7/G7 -> 0.017848721 | K7: =I7/G7 -> 0.0226727
A8: Rice and broken grain | B8: 2024-25 | C8: =718-0.51*1039 -> 188.11 | D8: =718-0.48*1039 -> 219.28 | E8: 370 | F8: 470 | G8: 1501.84 | H8: =C8*10000000/F8/100000 -> 40.023404 | I8: =D8*10000000/E8/100000 -> 59.264865 | J8: =H8/G8 -> 0.026649579 | K8: =I8/G8 -> 0.039461504
A9: Sugarcane (juice route, upper bound) | B9: 2023-24 | C9: 270.27 | D9: 270.27 | E9: 70 | F9: 81 | G9: 4531.58 | H9: =C9*10000000/F9/100000 -> 333.66667 | I9: =D9*10000000/E9/100000 -> 386.1 | J9: =H9/G9 -> 0.073631419 | K9: =I9/G9 -> 0.085202071
A10: Sugarcane (juice route, upper bound) | B10: 2024-25 | C10: 321 | D10: 321 | E10: 70 | F10: 81 | G10: 4546.11 | H10: =C10*10000000/F10/100000 -> 396.2963 | I10: =D10*10000000/E10/100000 -> 458.57143 | J10: =H10/G10 -> 0.087172615 | K10: =I10/G10 -> 0.10087117
A12: Ethanol volumes: 2023-24 Indian Express split; 2024-25 AIDA (grain 718, cane 321 crore L; maize 48-51% of 1,039). Yields: maize 380-400 and rice 370-385 L/t (Indian Express, Sep 2026); rice up to 470 L/t (Kisan Tak); cane juice 70-81 L/t (Jha et al. 2026).
A13: Cane lower bound is 0: ethanol from C-heavy molasses uses no extra cane. Production: DES time series (3rd AE 2025-26).

Sheet Analysis_H2H3
A1: H2 and H3: MSP rise vs output growth, and maize by season
A2: Changes 2015-16 to 2024-25. MSP from MSP_FRP tab; production from National_production tab (linked, green).
A4: Crop | B4: MSP 2015-16 | C4: MSP 2024-25 | D4: MSP rise | E4: Output 2015-16 (lakh t) | F4: Output 2024-25 (lakh t) | G4: Output growth | I4: Rank MSP | J4: Rank output
A5: Rice (paddy MSP) | B5: =MSP_FRP!C5 -> 1410 | C5: =MSP_FRP!L5 -> 2300 | D5: =C5/B5-1 -> 0.63120567 | E5: =National_production!B5 -> 1044.08 | F5: =National_production!B14 -> 1501.84 | G5: =F5/E5-1 -> 0.43843384 | I5: =RANK(D5,$D$5:$D$11,1) -> 3 | J5: =RANK(G5,$G$5:$G$11,1) -> 6
A6: Wheat | B6: =MSP_FRP!C13 -> 1525 | C6: =MSP_FRP!L13 -> 2425 | D6: =C6/B6-1 -> 0.59016393 | E6: =National_production!C5 -> 922.88 | F6: =National_production!C14 -> 1179.45 | G6: =F6/E6-1 -> 0.27801014 | I6: =RANK(D6,$D$5:$D$11,1) -> 2 | J6: =RANK(G6,$G$5:$G$11,1) -> 3
A7: Maize | B7: =MSP_FRP!C6 -> 1325 | C7: =MSP_FRP!L6 -> 2225 | D7: =C7/B7-1 -> 0.67924528 | E7: =National_production!D5 -> 225.67 | F7: =National_production!D14 -> 434.09 | G7: =F7/E7-1 -> 0.92356095 | I7: =RANK(D7,$D$5:$D$11,1) -> 4 | J7: =RANK(G7,$G$5:$G$11,1) -> 7
A8: Jowar | B8: =MSP_FRP!C7 -> 1570 | C8: =MSP_FRP!L7 -> 3371 | D8: =C8/B8-1 -> 1.1471338 | E8: =National_production!E5 -> 42.38 | F8: =National_production!E14 -> 49.55 | G8: =F8/E8-1 -> 0.16918358 | I8: =RANK(D8,$D$5:$D$11,1) -> 6 | J8: =RANK(G8,$G$5:$G$11,1) -> 2
A9: Bajra | B9: =MSP_FRP!C8 -> 1275 | C9: =MSP_FRP!L8 -> 2625 | D9: =C9/B9-1 -> 1.0588235 | E9: =National_production!F5 -> 80.67 | F9: =National_production!F14 -> 112.05 | G9: =F9/E9-1 -> 0.38899219 | I9: =RANK(D9,$D$5:$D$11,1) -> 5 | J9: =RANK(G9,$G$5:$G$11,1) -> 5
A10: Ragi | B10: =MSP_FRP!C9 -> 1650 | C10: =MSP_FRP!L9 -> 4290 | D10: =C10/B10-1 -> 1.6 | E10: =National_production!G5 -> 18.22 | F10: =National_production!G14 -> 19.77 | G10: =F10/E10-1 -> 0.08507135 | I10: =RANK(D10,$D$5:$D$11,1) -> 7 | J10: =RANK(G10,$G$5:$G$11,1) -> 1
A11: Sugarcane (FRP) | B11: =MSP_FRP!C14 -> 230 | C11: =MSP_FRP!L14 -> 340 | D11: =C11/B11-1 -> 0.47826087 | E11: =National_production!H5 -> 3484.48 | F11: =National_production!H14 -> 4546.11 | G11: =F11/E11-1 -> 0.30467387 | I11: =RANK(D11,$D$5:$D$11,1) -> 1 | J11: =RANK(G11,$G$5:$G$11,1) -> 4
A12: Rank correlation, MSP rise vs output growth | D12: =CORREL(I5:I11,J5:J11) -> -0.42857143
A14: All-India maize | B14: Season | C14: 2016-17 | D14: 2017-18 | E14: 2018-19 | F14: 2019-20 | G14: 2020-21 | H14: 2021-22 | I14: 2022-23 | J14: 2023-24 | K14: 2024-25 | L14: 2025-26 | M14: Change 2016-19 avg to 2022-25 avg
A15: Production (lakh t) | B15: Kharif | C15: =SUMIFS(UPAg_crops!$F$2:$F$951,UPAg_crops!$A$2:$A$951,"All India",UPAg_crops!$B$2:$B$951,"Maize",UPAg_crops!$C$2:$C$951,"Kharif",UPAg_crops!$D$2:$D$951,"2016-17") -> 189.19 | D15: =SUMIFS(UPAg_crops!$F$2:$F$951,UPAg_crops!$A$2:$A$951,"All India",UPAg_crops!$B$2:$B$951,"Maize",UPAg_crops!$C$2:$C$951,"Kharif",UPAg_crops!$D$2:$D$951,"2017-18") -> 201.18 | E15: =SUMIFS(UPAg_crops!$F$2:$F$951,UPAg_crops!$A$2:$A$951,"All India",UPAg_crops!$B$2:$B$951,"Maize",UPAg_crops!$C$2:$C$951,"Kharif",UPAg_crops!$D$2:$D$951,"2018-19") -> 194.14 | F15: =SUMIFS(UPAg_crops!$F$2:$F$951,UPAg_crops!$A$2:$A$951,"All India",UPAg_crops!$B$2:$B$951,"Maize",UPAg_crops!$C$2:$C$951,"Kharif",UPAg_crops!$D$2:$D$951,"2019-20") -> 194.29 | G15: =SUMIFS(UPAg_crops!$F$2:$F$951,UPAg_crops!$A$2:$A$951,"All India",UPAg_crops!$B$2:$B$951,"Maize",UPAg_crops!$C$2:$C$951,"Kharif",UPAg_crops!$D$2:$D$951,"2020-21") -> 215.55 | H15: =SUMIFS(UPAg_crops!$F$2:$F$951,UPAg_crops!$A$2:$A$951,"All India",UPAg_crops!$B$2:$B$951,"Maize",UPAg_crops!$C$2:$C$951,"Kharif",UPAg_crops!$D$2:$D$951,"2021-22") -> 226.81 | I15: =SUMIFS(UPAg_crops!$F$2:$F$951,UPAg_crops!$A$2:$A$951,"All India",UPAg_crops!$B$2:$B$951,"Maize",UPAg_crops!$C$2:$C$951,"Kharif",UPAg_crops!$D$2:$D$951,"2022-23") -> 236.74 | J15: =SUMIFS(UPAg_crops!$F$2:$F$951,UPAg_crops!$A$2:$A$951,"All India",UPAg_crops!$B$2:$B$951,"Maize",UPAg_crops!$C$2:$C$951,"Kharif",UPAg_crops!$D$2:$D$951,"2023-24") -> 222.45 | K15: =SUMIFS(UPAg_crops!$F$2:$F$951,UPAg_crops!$A$2:$A$951,"All India",UPAg_crops!$B$2:$B$951,"Maize",UPAg_crops!$C$2:$C$951,"Kharif",UPAg_crops!$D$2:$D$951,"2024-25") -> 248.08 | L15: =SUMIFS(UPAg_crops!$F$2:$F$951,UPAg_crops!$A$2:$A$951,"All India",UPAg_crops!$B$2:$B$951,"Maize",UPAg_crops!$C$2:$C$951,"Kharif",UPAg_crops!$D$2:$D$951,"2025-26") -> 305.09 | M15: =AVERAGE(I15:K15)/AVERAGE(C15:E15)-1 -> 0.21002207
A16: Production (lakh t) | B16: Rabi + Summer | C16: =SUMIFS(UPAg_crops!$F$2:$F$951,UPAg_crops!$A$2:$A$951,"All India",UPAg_crops!$B$2:$B$951,"Maize",UPAg_crops!$C$2:$C$951,"Rabi",UPAg_crops!$D$2:$D$951,"2016-17")+SUMIFS(UPAg_crops!$F$2:$F$951,UPAg_crops!$A$2:$A$951,"All India",UPAg_crops!$B$2:$B$951,"Maize",UPAg_crops!$C$2:$C$951,"Summer",UPAg_crops!$D$2:$D$951,"2016-17") -> 69.81 | D16: =SUMIFS(UPAg_crops!$F$2:$F$951,UPAg_crops!$A$2:$A$951,"All India",UPAg_crops!$B$2:$B$951,"Maize",UPAg_crops!$C$2:$C$951,"Rabi",UPAg_crops!$D$2:$D$951,"2017-18")+SUMIFS(UPAg_crops!$F$2:$F$951,UPAg_crops!$A$2:$A$951,"All India",UPAg_crops!$B$2:$B$951,"Maize",UPAg_crops!$C$2:$C$951,"Summer",UPAg_crops!$D$2:$D$951,"2017-18") -> 86.34 | E16: =SUMIFS(UPAg_crops!$F$2:$F$951,UPAg_crops!$A$2:$A$951,"All India",UPAg_crops!$B$2:$B$951,"Maize",UPAg_crops!$C$2:$C$951,"Rabi",UPAg_crops!$D$2:$D$951,"2018-19")+SUMIFS(UPAg_crops!$F$2:$F$951,UPAg_crops!$A$2:$A$951,"All India",UPAg_crops!$B$2:$B$951,"Maize",UPAg_crops!$C$2:$C$951,"Summer",UPAg_crops!$D$2:$D$951,"2018-19") -> 83.02 | F16: =SUMIFS(UPAg_crops!$F$2:$F$951,UPAg_crops!$A$2:$A$951,"All India",UPAg_crops!$B$2:$B$951,"Maize",UPAg_crops!$C$2:$C$951,"Rabi",UPAg_crops!$D$2:$D$951,"2019-20")+SUMIFS(UPAg_crops!$F$2:$F$951,UPAg_crops!$A$2:$A$951,"All India",UPAg_crops!$B$2:$B$951,"Maize",UPAg_crops!$C$2:$C$951,"Summer",UPAg_crops!$D$2:$D$951,"2019-20") -> 93.37 | G16: =SUMIFS(UPAg_crops!$F$2:$F$951,UPAg_crops!$A$2:$A$951,"All India",UPAg_crops!$B$2:$B$951,"Maize",UPAg_crops!$C$2:$C$951,"Rabi",UPAg_crops!$D$2:$D$951,"2020-21")+SUMIFS(UPAg_crops!$F$2:$F$951,UPAg_crops!$A$2:$A$951,"All India",UPAg_crops!$B$2:$B$951,"Maize",UPAg_crops!$C$2:$C$951,"Summer",UPAg_crops!$D$2:$D$951,"2020-21") -> 100.92 | H16: =SUMIFS(UPAg_crops!$F$2:$F$951,UPAg_crops!$A$2:$A$951,"All India",UPAg_crops!$B$2:$B$951,"Maize",UPAg_crops!$C$2:$C$951,"Rabi",UPAg_crops!$D$2:$D$951,"2021-22")+SUMIFS(UPAg_crops!$F$2:$F$951,UPAg_crops!$A$2:$A$951,"All India",UPAg_crops!$B$2:$B$951,"Maize",UPAg_crops!$C$2:$C$951,"Summer",UPAg_crops!$D$2:$D$951,"2021-22") -> 110.49 | I16: =SUMIFS(UPAg_crops!$F$2:$F$951,UPAg_crops!$A$2:$A$951,"All India",UPAg_crops!$B$2:$B$951,"Maize",UPAg_crops!$C$2:$C$951,"Rabi",UPAg_crops!$D$2:$D$951,"2022-23")+SUMIFS(UPAg_crops!$F$2:$F$951,UPAg_crops!$A$2:$A$951,"All India",UPAg_crops!$B$2:$B$951,"Maize",UPAg_crops!$C$2:$C$951,"Summer",UPAg_crops!$D$2:$D$951,"2022-23") -> 144.11 | J16: =SUMIFS(UPAg_crops!$F$2:$F$951,UPAg_crops!$A$2:$A$951,"All India",UPAg_crops!$B$2:$B$951,"Maize",UPAg_crops!$C$2:$C$951,"Rabi",UPAg_crops!$D$2:$D$951,"2023-24")+SUMIFS(UPAg_crops!$F$2:$F$951,UPAg_crops!$A$2:$A$951,"All India",UPAg_crops!$B$2:$B$951,"Maize",UPAg_crops!$C$2:$C$951,"Summer",UPAg_crops!$D$2:$D$951,"2023-24") -> 154.2 | K16: =SUMIFS(UPAg_crops!$F$2:$F$951,UPAg_crops!$A$2:$A$951,"All India",UPAg_crops!$B$2:$B$951,"Maize",UPAg_crops!$C$2:$C$951,"Rabi",UPAg_crops!$D$2:$D$951,"2024-25")+SUMIFS(UPAg_crops!$F$2:$F$951,UPAg_crops!$A$2:$A$951,"All India",UPAg_crops!$B$2:$B$951,"Maize",UPAg_crops!$C$2:$C$951,"Summer",UPAg_crops!$D$2:$D$951,"2024-25") -> 186 | L16: =SUMIFS(UPAg_crops!$F$2:$F$951,UPAg_crops!$A$2:$A$951,"All India",UPAg_crops!$B$2:$B$951,"Maize",UPAg_crops!$C$2:$C$951,"Rabi",UPAg_crops!$D$2:$D$951,"2025-26")+SUMIFS(UPAg_crops!$F$2:$F$951,UPAg_crops!$A$2:$A$951,"All India",UPAg_crops!$B$2:$B$951,"Maize",UPAg_crops!$C$2:$C$951,"Summer",UPAg_crops!$D$2:$D$951,"2025-26") -> 245.84 | M16: =AVERAGE(I16:K16)/AVERAGE(C16:E16)-1 -> 1.0249613
A17: Area (lakh ha) | B17: Kharif | C17: =SUMIFS(UPAg_crops!$E$2:$E$951,UPAg_crops!$A$2:$A$951,"All India",UPAg_crops!$B$2:$B$951,"Maize",UPAg_crops!$C$2:$C$951,"Kharif",UPAg_crops!$D$2:$D$951,"2016-17") -> 78.42 | D17: =SUMIFS(UPAg_crops!$E$2:$E$951,UPAg_crops!$A$2:$A$951,"All India",UPAg_crops!$B$2:$B$951,"Maize",UPAg_crops!$C$2:$C$951,"Kharif",UPAg_crops!$D$2:$D$951,"2017-18") -> 74.34 | E17: =SUMIFS(UPAg_crops!$E$2:$E$951,UPAg_crops!$A$2:$A$951,"All India",UPAg_crops!$B$2:$B$951,"Maize",UPAg_crops!$C$2:$C$951,"Kharif",UPAg_crops!$D$2:$D$951,"2018-19") -> 73.31 | F17: =SUMIFS(UPAg_crops!$E$2:$E$951,UPAg_crops!$A$2:$A$951,"All India",UPAg_crops!$B$2:$B$951,"Maize",UPAg_crops!$C$2:$C$951,"Kharif",UPAg_crops!$D$2:$D$951,"2019-20") -> 75.53 | G17: =SUMIFS(UPAg_crops!$E$2:$E$951,UPAg_crops!$A$2:$A$951,"All India",UPAg_crops!$B$2:$B$951,"Maize",UPAg_crops!$C$2:$C$951,"Kharif",UPAg_crops!$D$2:$D$951,"2020-21") -> 77.55 | H17: =SUMIFS(UPAg_crops!$E$2:$E$951,UPAg_crops!$A$2:$A$951,"All India",UPAg_crops!$B$2:$B$951,"Maize",UPAg_crops!$C$2:$C$951,"Kharif",UPAg_crops!$D$2:$D$951,"2021-22") -> 77.85 | I17: =SUMIFS(UPAg_crops!$E$2:$E$951,UPAg_crops!$A$2:$A$951,"All India",UPAg_crops!$B$2:$B$951,"Maize",UPAg_crops!$C$2:$C$951,"Kharif",UPAg_crops!$D$2:$D$951,"2022-23") -> 80.53 | J17: =SUMIFS(UPAg_crops!$E$2:$E$951,UPAg_crops!$A$2:$A$951,"All India",UPAg_crops!$B$2:$B$951,"Maize",UPAg_crops!$C$2:$C$951,"Kharif",UPAg_crops!$D$2:$D$951,"2023-24") -> 83.29 | K17: =SUMIFS(UPAg_crops!$E$2:$E$951,UPAg_crops!$A$2:$A$951,"All India",UPAg_crops!$B$2:$B$951,"Maize",UPAg_crops!$C$2:$C$951,"Kharif",UPAg_crops!$D$2:$D$951,"2024-25") -> 84.61 | L17: =SUMIFS(UPAg_crops!$E$2:$E$951,UPAg_crops!$A$2:$A$951,"All India",UPAg_crops!$B$2:$B$951,"Maize",UPAg_crops!$C$2:$C$951,"Kharif",UPAg_crops!$D$2:$D$951,"2025-26") -> 98.61 | M17: =AVERAGE(I17:K17)/AVERAGE(C17:E17)-1 -> 0.098907418
